 * Serving Flask app "final4" (lazy loading)
 * Environment: production
   WARNING: This is a development server. Do not use it in a production deployment.
   Use a production WSGI server instead.
 * Debug mode: on
 * Running on http://10.21.74.44:5000/ (Press CTRL+C to quit)
 * Restarting with stat
 * Debugger is active!
 * Debugger PIN: 325-183-733
10.25.135.101 - - [31/Mar/2020 11:11:49] "GET /search?fullname=test1.testSN1 HTTP/1.1" 200 -
10.25.135.101 - - [31/Mar/2020 11:11:56] "GET /search?fullname=test1.testSN1 HTTP/1.1" 200 -
10.25.135.101 - - [31/Mar/2020 13:03:03] "GET /search?fullname=test1.testSN14 HTTP/1.1" 404 -
10.25.135.101 - - [31/Mar/2020 15:20:10] "GET /search?fullname=test1.testSN14 HTTP/1.1" 404 -
10.25.135.101 - - [31/Mar/2020 15:20:14] "GET /search?fullname=test1.testSN1 HTTP/1.1" 200 -
10.25.132.128 - - [01/Apr/2020 14:21:58] "GET /search?fullname=test1.testSN1 HTTP/1.1" 200 -
10.25.132.128 - - [01/Apr/2020 16:25:13] "GET /search?fullname=test1.testSN1 HTTP/1.1" 200 -
10.21.74.41 - - [02/Apr/2020 10:46:10] "HEAD /search HTTP/1.1" 500 -
Traceback (most recent call last):
  File "/root/.venvs/testflask/lib/python3.6/site-packages/flask/app.py", line 2463, in __call__
    return self.wsgi_app(environ, start_response)
  File "/root/.venvs/testflask/lib/python3.6/site-packages/flask/app.py", line 2449, in wsgi_app
    response = self.handle_exception(e)
  File "/root/.venvs/testflask/lib/python3.6/site-packages/flask/app.py", line 1866, in handle_exception
    reraise(exc_type, exc_value, tb)
  File "/root/.venvs/testflask/lib/python3.6/site-packages/flask/_compat.py", line 39, in reraise
    raise value
  File "/root/.venvs/testflask/lib/python3.6/site-packages/flask/app.py", line 2446, in wsgi_app
    response = self.full_dispatch_request()
  File "/root/.venvs/testflask/lib/python3.6/site-packages/flask/app.py", line 1952, in full_dispatch_request
    return self.finalize_request(rv)
  File "/root/.venvs/testflask/lib/python3.6/site-packages/flask/app.py", line 1967, in finalize_request
    response = self.make_response(rv)
  File "/root/.venvs/testflask/lib/python3.6/site-packages/flask/app.py", line 2097, in make_response
    "The view function did not return a valid response. The"
TypeError: The view function did not return a valid response. The function either returned None or ended without a return statement.
10.25.129.239 - - [02/Apr/2020 12:08:59] "GET /search?fullname=test1.testSN1 HTTP/1.1" 200 -
 * Detected change in '/root/flaskapi/dev/OID/final4.py', reloading
 * Restarting with stat
 * Debugger is active!
 * Debugger PIN: 325-183-733
10.25.129.239 - - [02/Apr/2020 12:16:36] "GET /search?fullname=test1.testSN1 HTTP/1.1" 200 -
 * Detected change in '/root/flaskapi/dev/OID/final4.py', reloading
 * Restarting with stat
 * Debugger is active!
 * Debugger PIN: 325-183-733
10.25.129.239 - - [02/Apr/2020 12:17:12] "GET /search?fullname=test1.testSN1 HTTP/1.1" 200 -
10.25.129.239 - - [02/Apr/2020 12:18:39] "GET /search?fullname=test1.testSN1 HTTP/1.1" 200 -
