 * Serving Flask app "final4" (lazy loading)
 * Environment: production
   WARNING: This is a development server. Do not use it in a production deployment.
   Use a production WSGI server instead.
 * Debug mode: on
 * Running on http://10.21.74.44:5000/ (Press CTRL+C to quit)
 * Restarting with stat
 * Debugger is active!
 * Debugger PIN: 325-183-733
10.25.135.101 - - [31/Mar/2020 11:11:49] "GET /search?fullname=test1.testSN1 HTTP/1.1" 200 -
10.25.135.101 - - [31/Mar/2020 11:11:56] "GET /search?fullname=test1.testSN1 HTTP/1.1" 200 -
10.25.135.101 - - [31/Mar/2020 13:03:03] "GET /search?fullname=test1.testSN14 HTTP/1.1" 404 -
10.25.135.101 - - [31/Mar/2020 15:20:10] "GET /search?fullname=test1.testSN14 HTTP/1.1" 404 -
10.25.135.101 - - [31/Mar/2020 15:20:14] "GET /search?fullname=test1.testSN1 HTTP/1.1" 200 -
10.25.132.128 - - [01/Apr/2020 14:21:58] "GET /search?fullname=test1.testSN1 HTTP/1.1" 200 -
10.25.132.128 - - [01/Apr/2020 16:25:13] "GET /search?fullname=test1.testSN1 HTTP/1.1" 200 -
10.21.74.41 - - [02/Apr/2020 10:46:10] "HEAD /search HTTP/1.1" 500 -
Traceback (most recent call last):
  File "/root/.venvs/testflask/lib/python3.6/site-packages/flask/app.py", line 2463, in __call__
    return self.wsgi_app(environ, start_response)
  File "/root/.venvs/testflask/lib/python3.6/site-packages/flask/app.py", line 2449, in wsgi_app
    response = self.handle_exception(e)
  File "/root/.venvs/testflask/lib/python3.6/site-packages/flask/app.py", line 1866, in handle_exception
    reraise(exc_type, exc_value, tb)
  File "/root/.venvs/testflask/lib/python3.6/site-packages/flask/_compat.py", line 39, in reraise
    raise value
  File "/root/.venvs/testflask/lib/python3.6/site-packages/flask/app.py", line 2446, in wsgi_app
    response = self.full_dispatch_request()
  File "/root/.venvs/testflask/lib/python3.6/site-packages/flask/app.py", line 1952, in full_dispatch_request
    return self.finalize_request(rv)
  File "/root/.venvs/testflask/lib/python3.6/site-packages/flask/app.py", line 1967, in finalize_request
    response = self.make_response(rv)
  File "/root/.venvs/testflask/lib/python3.6/site-packages/flask/app.py", line 2097, in make_response
    "The view function did not return a valid response. The"
TypeError: The view function did not return a valid response. The function either returned None or ended without a return statement.
10.25.129.239 - - [02/Apr/2020 12:08:59] "GET /search?fullname=test1.testSN1 HTTP/1.1" 200 -
 * Detected change in '/root/flaskapi/dev/OID/final4.py', reloading
 * Restarting with stat
 * Debugger is active!
 * Debugger PIN: 325-183-733
10.25.129.239 - - [02/Apr/2020 12:16:36] "GET /search?fullname=test1.testSN1 HTTP/1.1" 200 -
 * Detected change in '/root/flaskapi/dev/OID/final4.py', reloading
 * Restarting with stat
 * Debugger is active!
 * Debugger PIN: 325-183-733
10.25.129.239 - - [02/Apr/2020 12:17:12] "GET /search?fullname=test1.testSN1 HTTP/1.1" 200 -
10.25.129.239 - - [02/Apr/2020 12:18:39] "GET /search?fullname=test1.testSN1 HTTP/1.1" 200 -
10.25.129.239 - - [02/Apr/2020 12:21:24] "GET /search?fullname=test1.testSN1 HTTP/1.1" 200 -
10.25.131.45 - - [02/Apr/2020 20:59:13] "GET /create HTTP/1.1" 405 -
10.25.131.135 - - [03/Apr/2020 10:21:49] "GET /search?fullname=test1.testSN1 HTTP/1.1" 200 -
10.25.134.47 - - [03/Apr/2020 11:09:57] "GET /create HTTP/1.1" 405 -
10.25.134.47 - - [03/Apr/2020 11:09:57] "GET /favicon.ico HTTP/1.1" 404 -
10.21.74.41 - - [03/Apr/2020 12:34:36] "HEAD /search HTTP/1.1" 500 -
Traceback (most recent call last):
  File "/root/.venvs/testflask/lib/python3.6/site-packages/flask/app.py", line 2463, in __call__
    return self.wsgi_app(environ, start_response)
  File "/root/.venvs/testflask/lib/python3.6/site-packages/flask/app.py", line 2449, in wsgi_app
    response = self.handle_exception(e)
  File "/root/.venvs/testflask/lib/python3.6/site-packages/flask/app.py", line 1866, in handle_exception
    reraise(exc_type, exc_value, tb)
  File "/root/.venvs/testflask/lib/python3.6/site-packages/flask/_compat.py", line 39, in reraise
    raise value
  File "/root/.venvs/testflask/lib/python3.6/site-packages/flask/app.py", line 2446, in wsgi_app
    response = self.full_dispatch_request()
  File "/root/.venvs/testflask/lib/python3.6/site-packages/flask/app.py", line 1952, in full_dispatch_request
    return self.finalize_request(rv)
  File "/root/.venvs/testflask/lib/python3.6/site-packages/flask/app.py", line 1967, in finalize_request
    response = self.make_response(rv)
  File "/root/.venvs/testflask/lib/python3.6/site-packages/flask/app.py", line 2097, in make_response
    "The view function did not return a valid response. The"
TypeError: The view function did not return a valid response. The function either returned None or ended without a return statement.
10.21.74.41 - - [03/Apr/2020 12:35:12] "HEAD / HTTP/1.1" 404 -
10.21.74.41 - - [03/Apr/2020 12:35:18] "HEAD / HTTP/1.1" 404 -
10.21.74.41 - - [03/Apr/2020 12:35:24] "HEAD / HTTP/1.1" 404 -
10.25.131.135 - - [03/Apr/2020 12:35:30] "GET / HTTP/1.1" 404 -
10.25.131.135 - - [03/Apr/2020 12:35:32] "GET /favicon.ico HTTP/1.1" 404 -
10.21.74.41 - - [03/Apr/2020 12:35:50] "HEAD /search HTTP/1.1" 500 -
Traceback (most recent call last):
  File "/root/.venvs/testflask/lib/python3.6/site-packages/flask/app.py", line 2463, in __call__
    return self.wsgi_app(environ, start_response)
  File "/root/.venvs/testflask/lib/python3.6/site-packages/flask/app.py", line 2449, in wsgi_app
    response = self.handle_exception(e)
  File "/root/.venvs/testflask/lib/python3.6/site-packages/flask/app.py", line 1866, in handle_exception
    reraise(exc_type, exc_value, tb)
  File "/root/.venvs/testflask/lib/python3.6/site-packages/flask/_compat.py", line 39, in reraise
    raise value
  File "/root/.venvs/testflask/lib/python3.6/site-packages/flask/app.py", line 2446, in wsgi_app
    response = self.full_dispatch_request()
  File "/root/.venvs/testflask/lib/python3.6/site-packages/flask/app.py", line 1952, in full_dispatch_request
    return self.finalize_request(rv)
  File "/root/.venvs/testflask/lib/python3.6/site-packages/flask/app.py", line 1967, in finalize_request
    response = self.make_response(rv)
  File "/root/.venvs/testflask/lib/python3.6/site-packages/flask/app.py", line 2097, in make_response
    "The view function did not return a valid response. The"
TypeError: The view function did not return a valid response. The function either returned None or ended without a return statement.
10.21.74.41 - - [03/Apr/2020 12:38:54] "GET /search/search?fullname=h HTTP/1.1" 404 -
10.21.74.41 - - [03/Apr/2020 12:39:22] "GET /search/search?fullname=test1.testSN1 HTTP/1.1" 404 -
10.21.74.41 - - [03/Apr/2020 12:40:43] "HEAD /search HTTP/1.1" 500 -
10.21.74.41 - - [03/Apr/2020 12:41:15] "GET /search/search?fullname=test1.testSN1 HTTP/1.1" 404 -
10.21.74.41 - - [03/Apr/2020 12:46:18] "HEAD /search HTTP/1.1" 500 -
Traceback (most recent call last):
  File "/root/.venvs/testflask/lib/python3.6/site-packages/flask/app.py", line 2463, in __call__
    return self.wsgi_app(environ, start_response)
  File "/root/.venvs/testflask/lib/python3.6/site-packages/flask/app.py", line 2449, in wsgi_app
    response = self.handle_exception(e)
  File "/root/.venvs/testflask/lib/python3.6/site-packages/flask/app.py", line 1866, in handle_exception
    reraise(exc_type, exc_value, tb)
  File "/root/.venvs/testflask/lib/python3.6/site-packages/flask/_compat.py", line 39, in reraise
    raise value
  File "/root/.venvs/testflask/lib/python3.6/site-packages/flask/app.py", line 2446, in wsgi_app
    response = self.full_dispatch_request()
  File "/root/.venvs/testflask/lib/python3.6/site-packages/flask/app.py", line 1952, in full_dispatch_request
    return self.finalize_request(rv)
  File "/root/.venvs/testflask/lib/python3.6/site-packages/flask/app.py", line 1967, in finalize_request
    response = self.make_response(rv)
  File "/root/.venvs/testflask/lib/python3.6/site-packages/flask/app.py", line 2097, in make_response
    "The view function did not return a valid response. The"
TypeError: The view function did not return a valid response. The function either returned None or ended without a return statement.
10.21.74.41 - - [03/Apr/2020 12:46:21] "HEAD /search HTTP/1.1" 500 -
Traceback (most recent call last):
  File "/root/.venvs/testflask/lib/python3.6/site-packages/flask/app.py", line 2463, in __call__
    return self.wsgi_app(environ, start_response)
  File "/root/.venvs/testflask/lib/python3.6/site-packages/flask/app.py", line 2449, in wsgi_app
    response = self.handle_exception(e)
  File "/root/.venvs/testflask/lib/python3.6/site-packages/flask/app.py", line 1866, in handle_exception
    reraise(exc_type, exc_value, tb)
  File "/root/.venvs/testflask/lib/python3.6/site-packages/flask/_compat.py", line 39, in reraise
    raise value
  File "/root/.venvs/testflask/lib/python3.6/site-packages/flask/app.py", line 2446, in wsgi_app
    response = self.full_dispatch_request()
  File "/root/.venvs/testflask/lib/python3.6/site-packages/flask/app.py", line 1952, in full_dispatch_request
    return self.finalize_request(rv)
  File "/root/.venvs/testflask/lib/python3.6/site-packages/flask/app.py", line 1967, in finalize_request
    response = self.make_response(rv)
  File "/root/.venvs/testflask/lib/python3.6/site-packages/flask/app.py", line 2097, in make_response
    "The view function did not return a valid response. The"
TypeError: The view function did not return a valid response. The function either returned None or ended without a return statement.
10.21.74.41 - - [03/Apr/2020 12:47:59] "GET /search/search?fullname=h HTTP/1.1" 404 -
10.25.131.135 - - [03/Apr/2020 12:49:26] "GET /search?fullname=test1.testSN1 HTTP/1.1" 200 -
10.21.74.41 - - [03/Apr/2020 12:50:39] "HEAD /search?fullname HTTP/1.1" 500 -
Traceback (most recent call last):
  File "/root/.venvs/testflask/lib/python3.6/site-packages/flask/app.py", line 2463, in __call__
    return self.wsgi_app(environ, start_response)
  File "/root/.venvs/testflask/lib/python3.6/site-packages/flask/app.py", line 2449, in wsgi_app
    response = self.handle_exception(e)
  File "/root/.venvs/testflask/lib/python3.6/site-packages/flask/app.py", line 1866, in handle_exception
    reraise(exc_type, exc_value, tb)
  File "/root/.venvs/testflask/lib/python3.6/site-packages/flask/_compat.py", line 39, in reraise
    raise value
  File "/root/.venvs/testflask/lib/python3.6/site-packages/flask/app.py", line 2446, in wsgi_app
    response = self.full_dispatch_request()
  File "/root/.venvs/testflask/lib/python3.6/site-packages/flask/app.py", line 1952, in full_dispatch_request
    return self.finalize_request(rv)
  File "/root/.venvs/testflask/lib/python3.6/site-packages/flask/app.py", line 1967, in finalize_request
    response = self.make_response(rv)
  File "/root/.venvs/testflask/lib/python3.6/site-packages/flask/app.py", line 2097, in make_response
    "The view function did not return a valid response. The"
TypeError: The view function did not return a valid response. The function either returned None or ended without a return statement.
10.21.74.41 - - [03/Apr/2020 12:50:53] "HEAD /search?q HTTP/1.1" 500 -
Traceback (most recent call last):
  File "/root/.venvs/testflask/lib/python3.6/site-packages/flask/app.py", line 2463, in __call__
    return self.wsgi_app(environ, start_response)
  File "/root/.venvs/testflask/lib/python3.6/site-packages/flask/app.py", line 2449, in wsgi_app
    response = self.handle_exception(e)
  File "/root/.venvs/testflask/lib/python3.6/site-packages/flask/app.py", line 1866, in handle_exception
    reraise(exc_type, exc_value, tb)
  File "/root/.venvs/testflask/lib/python3.6/site-packages/flask/_compat.py", line 39, in reraise
    raise value
  File "/root/.venvs/testflask/lib/python3.6/site-packages/flask/app.py", line 2446, in wsgi_app
    response = self.full_dispatch_request()
  File "/root/.venvs/testflask/lib/python3.6/site-packages/flask/app.py", line 1952, in full_dispatch_request
    return self.finalize_request(rv)
  File "/root/.venvs/testflask/lib/python3.6/site-packages/flask/app.py", line 1967, in finalize_request
    response = self.make_response(rv)
  File "/root/.venvs/testflask/lib/python3.6/site-packages/flask/app.py", line 2097, in make_response
    "The view function did not return a valid response. The"
TypeError: The view function did not return a valid response. The function either returned None or ended without a return statement.
10.21.74.41 - - [03/Apr/2020 12:50:58] "HEAD /search?q HTTP/1.1" 500 -
Traceback (most recent call last):
  File "/root/.venvs/testflask/lib/python3.6/site-packages/flask/app.py", line 2463, in __call__
    return self.wsgi_app(environ, start_response)
  File "/root/.venvs/testflask/lib/python3.6/site-packages/flask/app.py", line 2449, in wsgi_app
    response = self.handle_exception(e)
  File "/root/.venvs/testflask/lib/python3.6/site-packages/flask/app.py", line 1866, in handle_exception
    reraise(exc_type, exc_value, tb)
  File "/root/.venvs/testflask/lib/python3.6/site-packages/flask/_compat.py", line 39, in reraise
    raise value
  File "/root/.venvs/testflask/lib/python3.6/site-packages/flask/app.py", line 2446, in wsgi_app
    response = self.full_dispatch_request()
  File "/root/.venvs/testflask/lib/python3.6/site-packages/flask/app.py", line 1952, in full_dispatch_request
    return self.finalize_request(rv)
  File "/root/.venvs/testflask/lib/python3.6/site-packages/flask/app.py", line 1967, in finalize_request
    response = self.make_response(rv)
  File "/root/.venvs/testflask/lib/python3.6/site-packages/flask/app.py", line 2097, in make_response
    "The view function did not return a valid response. The"
TypeError: The view function did not return a valid response. The function either returned None or ended without a return statement.
10.21.74.41 - - [03/Apr/2020 12:51:23] "GET /search?q/search?fullname=h HTTP/1.1" 500 -
Traceback (most recent call last):
  File "/root/.venvs/testflask/lib/python3.6/site-packages/flask/app.py", line 2463, in __call__
    return self.wsgi_app(environ, start_response)
  File "/root/.venvs/testflask/lib/python3.6/site-packages/flask/app.py", line 2449, in wsgi_app
    response = self.handle_exception(e)
  File "/root/.venvs/testflask/lib/python3.6/site-packages/flask/app.py", line 1866, in handle_exception
    reraise(exc_type, exc_value, tb)
  File "/root/.venvs/testflask/lib/python3.6/site-packages/flask/_compat.py", line 39, in reraise
    raise value
  File "/root/.venvs/testflask/lib/python3.6/site-packages/flask/app.py", line 2446, in wsgi_app
    response = self.full_dispatch_request()
  File "/root/.venvs/testflask/lib/python3.6/site-packages/flask/app.py", line 1951, in full_dispatch_request
    rv = self.handle_user_exception(e)
  File "/root/.venvs/testflask/lib/python3.6/site-packages/flask/app.py", line 1820, in handle_user_exception
    reraise(exc_type, exc_value, tb)
  File "/root/.venvs/testflask/lib/python3.6/site-packages/flask/_compat.py", line 39, in reraise
    raise value
  File "/root/.venvs/testflask/lib/python3.6/site-packages/flask/app.py", line 1949, in full_dispatch_request
    rv = self.dispatch_request()
  File "/root/.venvs/testflask/lib/python3.6/site-packages/flask/app.py", line 1935, in dispatch_request
    return self.view_functions[rule.endpoint](**req.view_args)
  File "/root/flaskapi/dev/OID/final4.py", line 158, in search
    con.simple_bind_s(request.authorization["username"],request.authorization["password"])
TypeError: 'NoneType' object is not subscriptable
10.21.74.41 - - [03/Apr/2020 12:53:25] "GET /search?q/search?fullname=test1.testSN1 HTTP/1.1" 500 -
Traceback (most recent call last):
  File "/root/.venvs/testflask/lib/python3.6/site-packages/flask/app.py", line 2463, in __call__
    return self.wsgi_app(environ, start_response)
  File "/root/.venvs/testflask/lib/python3.6/site-packages/flask/app.py", line 2449, in wsgi_app
    response = self.handle_exception(e)
  File "/root/.venvs/testflask/lib/python3.6/site-packages/flask/app.py", line 1866, in handle_exception
    reraise(exc_type, exc_value, tb)
  File "/root/.venvs/testflask/lib/python3.6/site-packages/flask/_compat.py", line 39, in reraise
    raise value
  File "/root/.venvs/testflask/lib/python3.6/site-packages/flask/app.py", line 2446, in wsgi_app
    response = self.full_dispatch_request()
  File "/root/.venvs/testflask/lib/python3.6/site-packages/flask/app.py", line 1951, in full_dispatch_request
    rv = self.handle_user_exception(e)
  File "/root/.venvs/testflask/lib/python3.6/site-packages/flask/app.py", line 1820, in handle_user_exception
    reraise(exc_type, exc_value, tb)
  File "/root/.venvs/testflask/lib/python3.6/site-packages/flask/_compat.py", line 39, in reraise
    raise value
  File "/root/.venvs/testflask/lib/python3.6/site-packages/flask/app.py", line 1949, in full_dispatch_request
    rv = self.dispatch_request()
  File "/root/.venvs/testflask/lib/python3.6/site-packages/flask/app.py", line 1935, in dispatch_request
    return self.view_functions[rule.endpoint](**req.view_args)
  File "/root/flaskapi/dev/OID/final4.py", line 158, in search
    con.simple_bind_s(request.authorization["username"],request.authorization["password"])
TypeError: 'NoneType' object is not subscriptable
10.21.74.41 - - [03/Apr/2020 12:54:43] "GET /search?fullname/search?fullname=test1.testSN1 HTTP/1.1" 500 -
 * Serving Flask app "final4" (lazy loading)
 * Environment: production
   WARNING: This is a development server. Do not use it in a production deployment.
   Use a production WSGI server instead.
 * Debug mode: on
 * Running on http://10.21.74.44:5000/ (Press CTRL+C to quit)
 * Restarting with stat
 * Debugger is active!
 * Debugger PIN: 325-183-733
10.25.132.239 - - [06/Apr/2020 10:34:19] "POST /search HTTP/1.1" 405 -
10.25.132.239 - - [06/Apr/2020 10:34:25] "GET /search HTTP/1.1" 500 -
Traceback (most recent call last):
  File "/root/.venvs/testflask/lib/python3.6/site-packages/flask/app.py", line 2463, in __call__
    return self.wsgi_app(environ, start_response)
  File "/root/.venvs/testflask/lib/python3.6/site-packages/flask/app.py", line 2449, in wsgi_app
    response = self.handle_exception(e)
  File "/root/.venvs/testflask/lib/python3.6/site-packages/flask/app.py", line 1866, in handle_exception
    reraise(exc_type, exc_value, tb)
  File "/root/.venvs/testflask/lib/python3.6/site-packages/flask/_compat.py", line 39, in reraise
    raise value
  File "/root/.venvs/testflask/lib/python3.6/site-packages/flask/app.py", line 2446, in wsgi_app
    response = self.full_dispatch_request()
  File "/root/.venvs/testflask/lib/python3.6/site-packages/flask/app.py", line 1951, in full_dispatch_request
    rv = self.handle_user_exception(e)
  File "/root/.venvs/testflask/lib/python3.6/site-packages/flask/app.py", line 1820, in handle_user_exception
    reraise(exc_type, exc_value, tb)
  File "/root/.venvs/testflask/lib/python3.6/site-packages/flask/_compat.py", line 39, in reraise
    raise value
  File "/root/.venvs/testflask/lib/python3.6/site-packages/flask/app.py", line 1949, in full_dispatch_request
    rv = self.dispatch_request()
  File "/root/.venvs/testflask/lib/python3.6/site-packages/flask/app.py", line 1935, in dispatch_request
    return self.view_functions[rule.endpoint](**req.view_args)
  File "/root/flaskapi/dev/OID/final4.py", line 158, in search
    con.simple_bind_s(request.authorization["username"],request.authorization["password"])
TypeError: 'NoneType' object is not subscriptable
10.25.132.239 - - [06/Apr/2020 10:34:37] "GET /search?fullname=test1.testSN1 HTTP/1.1" 200 -
10.21.74.41 - - [06/Apr/2020 12:40:01] "HEAD /search HTTP/1.1" 500 -
Traceback (most recent call last):
  File "/root/.venvs/testflask/lib/python3.6/site-packages/flask/app.py", line 2463, in __call__
    return self.wsgi_app(environ, start_response)
  File "/root/.venvs/testflask/lib/python3.6/site-packages/flask/app.py", line 2449, in wsgi_app
    response = self.handle_exception(e)
  File "/root/.venvs/testflask/lib/python3.6/site-packages/flask/app.py", line 1866, in handle_exception
    reraise(exc_type, exc_value, tb)
  File "/root/.venvs/testflask/lib/python3.6/site-packages/flask/_compat.py", line 39, in reraise
    raise value
  File "/root/.venvs/testflask/lib/python3.6/site-packages/flask/app.py", line 2446, in wsgi_app
    response = self.full_dispatch_request()
  File "/root/.venvs/testflask/lib/python3.6/site-packages/flask/app.py", line 1952, in full_dispatch_request
    return self.finalize_request(rv)
  File "/root/.venvs/testflask/lib/python3.6/site-packages/flask/app.py", line 1967, in finalize_request
    response = self.make_response(rv)
  File "/root/.venvs/testflask/lib/python3.6/site-packages/flask/app.py", line 2097, in make_response
    "The view function did not return a valid response. The"
TypeError: The view function did not return a valid response. The function either returned None or ended without a return statement.
10.21.74.41 - - [06/Apr/2020 12:41:20] "GET /search/searchd HTTP/1.1" 404 -
10.21.74.41 - - [06/Apr/2020 12:49:15] "HEAD /search HTTP/1.1" 500 -
Traceback (most recent call last):
  File "/root/.venvs/testflask/lib/python3.6/site-packages/flask/app.py", line 2463, in __call__
    return self.wsgi_app(environ, start_response)
  File "/root/.venvs/testflask/lib/python3.6/site-packages/flask/app.py", line 2449, in wsgi_app
    response = self.handle_exception(e)
  File "/root/.venvs/testflask/lib/python3.6/site-packages/flask/app.py", line 1866, in handle_exception
    reraise(exc_type, exc_value, tb)
  File "/root/.venvs/testflask/lib/python3.6/site-packages/flask/_compat.py", line 39, in reraise
    raise value
  File "/root/.venvs/testflask/lib/python3.6/site-packages/flask/app.py", line 2446, in wsgi_app
    response = self.full_dispatch_request()
  File "/root/.venvs/testflask/lib/python3.6/site-packages/flask/app.py", line 1952, in full_dispatch_request
    return self.finalize_request(rv)
  File "/root/.venvs/testflask/lib/python3.6/site-packages/flask/app.py", line 1967, in finalize_request
    response = self.make_response(rv)
  File "/root/.venvs/testflask/lib/python3.6/site-packages/flask/app.py", line 2097, in make_response
    "The view function did not return a valid response. The"
TypeError: The view function did not return a valid response. The function either returned None or ended without a return statement.
10.21.74.41 - - [06/Apr/2020 12:50:01] "GET /search/ HTTP/1.1" 404 -
 * Serving Flask app "final4" (lazy loading)
 * Environment: production
   WARNING: This is a development server. Do not use it in a production deployment.
   Use a production WSGI server instead.
 * Debug mode: on
 * Running on http://10.21.74.44:5000/ (Press CTRL+C to quit)
 * Restarting with stat
 * Debugger is active!
 * Debugger PIN: 325-183-733
10.21.74.41 - - [07/Apr/2020 10:27:31] "HEAD / HTTP/1.1" 404 -
10.21.74.41 - - [07/Apr/2020 10:32:40] "GET /search?fullname=t HTTP/1.1" 400 -
10.21.74.41 - - [07/Apr/2020 10:33:03] "GET /search?fullname=test1.testSN1 HTTP/1.1" 400 -
10.21.74.41 - - [07/Apr/2020 10:34:40] "GET /search?fullname=test1.testSN1 HTTP/1.1" 200 -
10.21.74.41 - - [07/Apr/2020 10:39:49] "POST /delete HTTP/1.1" 500 -
Traceback (most recent call last):
  File "/root/flaskapi/dev/OID/final4.py", line 112, in delete
    con.simple_bind_s(request.authorization["username"],request.authorization["password"])
  File "/root/.venvs/testflask/lib/python3.6/site-packages/ldap/ldapobject.py", line 446, in simple_bind_s
    resp_type, resp_data, resp_msgid, resp_ctrls = self.result3(msgid,all=1,timeout=self.timeout)
  File "/root/.venvs/testflask/lib/python3.6/site-packages/ldap/ldapobject.py", line 751, in result3
    resp_ctrl_classes=resp_ctrl_classes
  File "/root/.venvs/testflask/lib/python3.6/site-packages/ldap/ldapobject.py", line 758, in result4
    ldap_result = self._ldap_call(self._l.result4,msgid,all,timeout,add_ctrls,add_intermediates,add_extop)
  File "/root/.venvs/testflask/lib/python3.6/site-packages/ldap/ldapobject.py", line 331, in _ldap_call
    reraise(exc_type, exc_value, exc_traceback)
  File "/root/.venvs/testflask/lib/python3.6/site-packages/ldap/compat.py", line 44, in reraise
    raise exc_value
  File "/root/.venvs/testflask/lib/python3.6/site-packages/ldap/ldapobject.py", line 315, in _ldap_call
    result = func(*args,**kwargs)
ldap.INVALID_CREDENTIALS: {'desc': 'Invalid credentials'}

During handling of the above exception, another exception occurred:

Traceback (most recent call last):
  File "/root/.venvs/testflask/lib/python3.6/site-packages/flask/app.py", line 2463, in __call__
    return self.wsgi_app(environ, start_response)
  File "/root/.venvs/testflask/lib/python3.6/site-packages/flask/app.py", line 2449, in wsgi_app
    response = self.handle_exception(e)
  File "/root/.venvs/testflask/lib/python3.6/site-packages/flask/app.py", line 1866, in handle_exception
    reraise(exc_type, exc_value, tb)
  File "/root/.venvs/testflask/lib/python3.6/site-packages/flask/_compat.py", line 39, in reraise
    raise value
  File "/root/.venvs/testflask/lib/python3.6/site-packages/flask/app.py", line 2446, in wsgi_app
    response = self.full_dispatch_request()
  File "/root/.venvs/testflask/lib/python3.6/site-packages/flask/app.py", line 1951, in full_dispatch_request
    rv = self.handle_user_exception(e)
  File "/root/.venvs/testflask/lib/python3.6/site-packages/flask/app.py", line 1820, in handle_user_exception
    reraise(exc_type, exc_value, tb)
  File "/root/.venvs/testflask/lib/python3.6/site-packages/flask/_compat.py", line 39, in reraise
    raise value
  File "/root/.venvs/testflask/lib/python3.6/site-packages/flask/app.py", line 1949, in full_dispatch_request
    rv = self.dispatch_request()
  File "/root/.venvs/testflask/lib/python3.6/site-packages/flask/app.py", line 1935, in dispatch_request
    return self.view_functions[rule.endpoint](**req.view_args)
  File "/root/flaskapi/dev/OID/final4.py", line 142, in delete
    rValue= "Error while deleting user " + "'"+ data['fullname'] + "': " + mssg
UnboundLocalError: local variable 'data' referenced before assignment
10.21.74.41 - - [07/Apr/2020 10:50:51] "GET /search?fullname=test.testSN1 HTTP/1.1" 400 -
10.21.74.41 - - [07/Apr/2020 10:51:52] "GET /search?fullname=test.testSN1 HTTP/1.1" 404 -
10.21.74.41 - - [07/Apr/2020 10:53:14] "POST /delete HTTP/1.1" 204 -
10.21.74.41 - - [07/Apr/2020 10:54:17] "POST /delete HTTP/1.1" 400 -
10.21.74.41 - - [07/Apr/2020 10:56:18] "GET /search?fullname=test1.testSN1 HTTP/1.1" 404 -
10.21.74.41 - - [07/Apr/2020 10:56:51] "POST /delete HTTP/1.1" 400 -
10.21.74.41 - - [07/Apr/2020 10:59:14] "GET /search?fullname=11 HTTP/1.1" 400 -
10.21.74.41 - - [07/Apr/2020 11:00:26] "GET /search?fullname=d HTTP/1.1" 404 -
10.21.74.41 - - [07/Apr/2020 11:00:50] "POST /delete HTTP/1.1" 400 -
10.21.74.41 - - [07/Apr/2020 11:01:37] "POST /create HTTP/1.1" 201 -
10.21.74.41 - - [07/Apr/2020 11:03:09] "POST /updateuser HTTP/1.1" 200 -
10.21.74.41 - - [07/Apr/2020 11:04:10] "POST /updatepassword HTTP/1.1" 200 -
10.21.74.41 - - [07/Apr/2020 12:05:57] "GET /search?fullname=res HTTP/1.1" 404 -
10.21.74.41 - - [07/Apr/2020 12:06:10] "GET /search?fullname=test1.testSN1 HTTP/1.1" 200 -
10.21.74.41 - - [07/Apr/2020 12:06:53] "POST /delete HTTP/1.1" 204 -
10.21.74.41 - - [07/Apr/2020 12:07:26] "POST /updatepassword HTTP/1.1" 404 -
10.21.74.41 - - [07/Apr/2020 12:07:37] "POST /updateuser HTTP/1.1" 400 -
10.25.128.171 - - [07/Apr/2020 12:39:58] "GET /hello HTTP/1.1" 404 -
10.25.128.171 - - [07/Apr/2020 12:40:09] "GET / HTTP/1.1" 404 -
10.25.128.171 - - [07/Apr/2020 12:40:15] "GET /search HTTP/1.1" 500 -
Traceback (most recent call last):
  File "/root/.venvs/testflask/lib/python3.6/site-packages/flask/app.py", line 2463, in __call__
    return self.wsgi_app(environ, start_response)
  File "/root/.venvs/testflask/lib/python3.6/site-packages/flask/app.py", line 2449, in wsgi_app
    response = self.handle_exception(e)
  File "/root/.venvs/testflask/lib/python3.6/site-packages/flask/app.py", line 1866, in handle_exception
    reraise(exc_type, exc_value, tb)
  File "/root/.venvs/testflask/lib/python3.6/site-packages/flask/_compat.py", line 39, in reraise
    raise value
  File "/root/.venvs/testflask/lib/python3.6/site-packages/flask/app.py", line 2446, in wsgi_app
    response = self.full_dispatch_request()
  File "/root/.venvs/testflask/lib/python3.6/site-packages/flask/app.py", line 1951, in full_dispatch_request
    rv = self.handle_user_exception(e)
  File "/root/.venvs/testflask/lib/python3.6/site-packages/flask/app.py", line 1820, in handle_user_exception
    reraise(exc_type, exc_value, tb)
  File "/root/.venvs/testflask/lib/python3.6/site-packages/flask/_compat.py", line 39, in reraise
    raise value
  File "/root/.venvs/testflask/lib/python3.6/site-packages/flask/app.py", line 1949, in full_dispatch_request
    rv = self.dispatch_request()
  File "/root/.venvs/testflask/lib/python3.6/site-packages/flask/app.py", line 1935, in dispatch_request
    return self.view_functions[rule.endpoint](**req.view_args)
  File "/root/flaskapi/dev/OID/final4.py", line 158, in search
    con.simple_bind_s(request.authorization["username"],request.authorization["password"])
TypeError: 'NoneType' object is not subscriptable
10.25.128.171 - - [07/Apr/2020 12:40:50] "GET /search?fullname=test HTTP/1.1" 500 -
Traceback (most recent call last):
  File "/root/.venvs/testflask/lib/python3.6/site-packages/flask/app.py", line 2463, in __call__
    return self.wsgi_app(environ, start_response)
  File "/root/.venvs/testflask/lib/python3.6/site-packages/flask/app.py", line 2449, in wsgi_app
    response = self.handle_exception(e)
  File "/root/.venvs/testflask/lib/python3.6/site-packages/flask/app.py", line 1866, in handle_exception
    reraise(exc_type, exc_value, tb)
  File "/root/.venvs/testflask/lib/python3.6/site-packages/flask/_compat.py", line 39, in reraise
    raise value
  File "/root/.venvs/testflask/lib/python3.6/site-packages/flask/app.py", line 2446, in wsgi_app
    response = self.full_dispatch_request()
  File "/root/.venvs/testflask/lib/python3.6/site-packages/flask/app.py", line 1951, in full_dispatch_request
    rv = self.handle_user_exception(e)
  File "/root/.venvs/testflask/lib/python3.6/site-packages/flask/app.py", line 1820, in handle_user_exception
    reraise(exc_type, exc_value, tb)
  File "/root/.venvs/testflask/lib/python3.6/site-packages/flask/_compat.py", line 39, in reraise
    raise value
  File "/root/.venvs/testflask/lib/python3.6/site-packages/flask/app.py", line 1949, in full_dispatch_request
    rv = self.dispatch_request()
  File "/root/.venvs/testflask/lib/python3.6/site-packages/flask/app.py", line 1935, in dispatch_request
    return self.view_functions[rule.endpoint](**req.view_args)
  File "/root/flaskapi/dev/OID/final4.py", line 158, in search
    con.simple_bind_s(request.authorization["username"],request.authorization["password"])
TypeError: 'NoneType' object is not subscriptable
10.21.74.41 - - [07/Apr/2020 12:53:43] "GET /search?fullname=test1.testSN1 HTTP/1.1" 404 -
10.21.74.41 - - [07/Apr/2020 12:54:15] "POST /create HTTP/1.1" 201 -
10.21.74.41 - - [07/Apr/2020 12:54:28] "GET /search?fullname=test1.testSN1 HTTP/1.1" 200 -
10.21.74.41 - - [07/Apr/2020 12:55:10] "POST /delete HTTP/1.1" 204 -
10.21.74.41 - - [07/Apr/2020 12:55:20] "GET /search?fullname=test1.testSN1 HTTP/1.1" 404 -
10.21.74.41 - - [07/Apr/2020 12:55:33] "POST /updateuser HTTP/1.1" 400 -
 * Serving Flask app "central6" (lazy loading)
 * Environment: production
   WARNING: This is a development server. Do not use it in a production deployment.
   Use a production WSGI server instead.
 * Debug mode: on
 * Running on http://10.21.74.44:5000/ (Press CTRL+C to quit)
 * Restarting with stat
 * Debugger is active!
 * Debugger PIN: 325-183-733
10.25.129.247 - - [05/May/2020 13:43:55] "POST /create HTTP/1.1" 201 -
10.25.129.247 - - [05/May/2020 13:44:10] "GET /search?username=test1.testSN1 HTTP/1.1" 200 -
10.25.133.203 - - [08/May/2020 15:29:14] "GET /search?username=test1.testSN1 HTTP/1.1" 200 -
10.46.194.155 - - [20/May/2020 23:33:54] "GET / HTTP/1.1" 404 -
10.46.194.155 - - [20/May/2020 23:33:54] "GET /favicon.ico HTTP/1.1" 404 -
10.46.194.155 - - [20/May/2020 23:34:10] "GET /create HTTP/1.1" 405 -
10.46.194.155 - - [20/May/2020 23:34:44] "GET /create HTTP/1.1" 405 -
10.46.194.155 - - [20/May/2020 23:36:44] "GET /search HTTP/1.1" 500 -
Traceback (most recent call last):
  File "/root/.venvs/testflask/lib/python3.6/site-packages/flask/app.py", line 2463, in __call__
    return self.wsgi_app(environ, start_response)
  File "/root/.venvs/testflask/lib/python3.6/site-packages/flask/app.py", line 2449, in wsgi_app
    response = self.handle_exception(e)
  File "/root/.venvs/testflask/lib/python3.6/site-packages/flask/app.py", line 1866, in handle_exception
    reraise(exc_type, exc_value, tb)
  File "/root/.venvs/testflask/lib/python3.6/site-packages/flask/_compat.py", line 39, in reraise
    raise value
  File "/root/.venvs/testflask/lib/python3.6/site-packages/flask/app.py", line 2446, in wsgi_app
    response = self.full_dispatch_request()
  File "/root/.venvs/testflask/lib/python3.6/site-packages/flask/app.py", line 1951, in full_dispatch_request
    rv = self.handle_user_exception(e)
  File "/root/.venvs/testflask/lib/python3.6/site-packages/flask/app.py", line 1820, in handle_user_exception
    reraise(exc_type, exc_value, tb)
  File "/root/.venvs/testflask/lib/python3.6/site-packages/flask/_compat.py", line 39, in reraise
    raise value
  File "/root/.venvs/testflask/lib/python3.6/site-packages/flask/app.py", line 1949, in full_dispatch_request
    rv = self.dispatch_request()
  File "/root/.venvs/testflask/lib/python3.6/site-packages/flask/app.py", line 1935, in dispatch_request
    return self.view_functions[rule.endpoint](**req.view_args)
  File "/root/flaskapi/dev/OID/central6.py", line 163, in search
    con.simple_bind_s(request.authorization["username"],request.authorization["password"])
TypeError: 'NoneType' object is not subscriptable
10.46.194.155 - - [20/May/2020 23:36:44] "GET /search?__debugger__=yes&cmd=resource&f=style.css HTTP/1.1" 200 -
10.46.194.155 - - [20/May/2020 23:36:44] "GET /search?__debugger__=yes&cmd=resource&f=jquery.js HTTP/1.1" 200 -
10.46.194.155 - - [20/May/2020 23:36:44] "GET /search?__debugger__=yes&cmd=resource&f=debugger.js HTTP/1.1" 200 -
10.46.194.155 - - [20/May/2020 23:36:44] "GET /search?__debugger__=yes&cmd=resource&f=ubuntu.ttf HTTP/1.1" 200 -
10.46.194.155 - - [20/May/2020 23:36:44] "GET /search?__debugger__=yes&cmd=resource&f=console.png HTTP/1.1" 200 -
10.46.194.155 - - [20/May/2020 23:36:44] "GET /search?__debugger__=yes&cmd=resource&f=console.png HTTP/1.1" 200 -
10.46.194.155 - - [20/May/2020 23:39:12] "GET /search?fullname=test HTTP/1.1" 500 -
Traceback (most recent call last):
  File "/root/.venvs/testflask/lib/python3.6/site-packages/flask/app.py", line 2463, in __call__
    return self.wsgi_app(environ, start_response)
  File "/root/.venvs/testflask/lib/python3.6/site-packages/flask/app.py", line 2449, in wsgi_app
    response = self.handle_exception(e)
  File "/root/.venvs/testflask/lib/python3.6/site-packages/flask/app.py", line 1866, in handle_exception
    reraise(exc_type, exc_value, tb)
  File "/root/.venvs/testflask/lib/python3.6/site-packages/flask/_compat.py", line 39, in reraise
    raise value
  File "/root/.venvs/testflask/lib/python3.6/site-packages/flask/app.py", line 2446, in wsgi_app
    response = self.full_dispatch_request()
  File "/root/.venvs/testflask/lib/python3.6/site-packages/flask/app.py", line 1951, in full_dispatch_request
    rv = self.handle_user_exception(e)
  File "/root/.venvs/testflask/lib/python3.6/site-packages/flask/app.py", line 1820, in handle_user_exception
    reraise(exc_type, exc_value, tb)
  File "/root/.venvs/testflask/lib/python3.6/site-packages/flask/_compat.py", line 39, in reraise
    raise value
  File "/root/.venvs/testflask/lib/python3.6/site-packages/flask/app.py", line 1949, in full_dispatch_request
    rv = self.dispatch_request()
  File "/root/.venvs/testflask/lib/python3.6/site-packages/flask/app.py", line 1935, in dispatch_request
    return self.view_functions[rule.endpoint](**req.view_args)
  File "/root/flaskapi/dev/OID/central6.py", line 163, in search
    con.simple_bind_s(request.authorization["username"],request.authorization["password"])
TypeError: 'NoneType' object is not subscriptable
10.46.194.155 - - [20/May/2020 23:39:12] "GET /search?__debugger__=yes&cmd=resource&f=style.css HTTP/1.1" 200 -
10.46.194.155 - - [20/May/2020 23:39:12] "GET /search?__debugger__=yes&cmd=resource&f=debugger.js HTTP/1.1" 200 -
10.46.194.155 - - [20/May/2020 23:39:12] "GET /search?__debugger__=yes&cmd=resource&f=jquery.js HTTP/1.1" 200 -
10.46.194.155 - - [20/May/2020 23:39:12] "GET /search?__debugger__=yes&cmd=resource&f=console.png HTTP/1.1" 200 -
10.46.194.155 - - [20/May/2020 23:39:12] "GET /search?__debugger__=yes&cmd=resource&f=ubuntu.ttf HTTP/1.1" 200 -
10.25.130.126 - - [26/May/2020 13:14:52] "POST /create HTTP/1.1" 201 -
10.25.128.60 - - [03/Jun/2020 11:37:02] "POST /create HTTP/1.1" 400 -
10.25.128.60 - - [03/Jun/2020 11:37:52] "POST /create HTTP/1.1" 400 -
 * Detected change in '/root/flaskapi/dev/OID/central6.py', reloading
{'desc': 'Invalid credentials'}
{'desc': 'Already exists', 'info': 'Object already exists'}
 * Restarting with stat
 * Debugger is active!
 * Debugger PIN: 325-183-733
10.25.128.60 - - [03/Jun/2020 11:39:09] "POST /create HTTP/1.1" 500 -
Traceback (most recent call last):
  File "/root/.venvs/testflask/lib/python3.6/site-packages/flask/app.py", line 2463, in __call__
    return self.wsgi_app(environ, start_response)
  File "/root/.venvs/testflask/lib/python3.6/site-packages/flask/app.py", line 2449, in wsgi_app
    response = self.handle_exception(e)
  File "/root/.venvs/testflask/lib/python3.6/site-packages/flask/app.py", line 1866, in handle_exception
    reraise(exc_type, exc_value, tb)
  File "/root/.venvs/testflask/lib/python3.6/site-packages/flask/_compat.py", line 39, in reraise
    raise value
  File "/root/.venvs/testflask/lib/python3.6/site-packages/flask/app.py", line 2446, in wsgi_app
    response = self.full_dispatch_request()
  File "/root/.venvs/testflask/lib/python3.6/site-packages/flask/app.py", line 1951, in full_dispatch_request
    rv = self.handle_user_exception(e)
  File "/root/.venvs/testflask/lib/python3.6/site-packages/flask/app.py", line 1820, in handle_user_exception
    reraise(exc_type, exc_value, tb)
  File "/root/.venvs/testflask/lib/python3.6/site-packages/flask/_compat.py", line 39, in reraise
    raise value
  File "/root/.venvs/testflask/lib/python3.6/site-packages/flask/app.py", line 1949, in full_dispatch_request
    rv = self.dispatch_request()
  File "/root/.venvs/testflask/lib/python3.6/site-packages/flask/app.py", line 1935, in dispatch_request
    return self.view_functions[rule.endpoint](**req.view_args)
  File "/root/flaskapi/dev/OID/central6.py", line 76, in create
    parsed_entry=[(i,bytes(j,encoding='utf-8'))for i,j in entry.items()]
  File "/root/flaskapi/dev/OID/central6.py", line 76, in <listcomp>
    parsed_entry=[(i,bytes(j,encoding='utf-8'))for i,j in entry.items()]
TypeError: encoding without a string argument
10.25.128.60 - - [03/Jun/2020 11:39:32] "POST /create HTTP/1.1" 500 -
Traceback (most recent call last):
  File "/root/.venvs/testflask/lib/python3.6/site-packages/flask/app.py", line 2463, in __call__
    return self.wsgi_app(environ, start_response)
  File "/root/.venvs/testflask/lib/python3.6/site-packages/flask/app.py", line 2449, in wsgi_app
    response = self.handle_exception(e)
  File "/root/.venvs/testflask/lib/python3.6/site-packages/flask/app.py", line 1866, in handle_exception
    reraise(exc_type, exc_value, tb)
  File "/root/.venvs/testflask/lib/python3.6/site-packages/flask/_compat.py", line 39, in reraise
    raise value
  File "/root/.venvs/testflask/lib/python3.6/site-packages/flask/app.py", line 2446, in wsgi_app
    response = self.full_dispatch_request()
  File "/root/.venvs/testflask/lib/python3.6/site-packages/flask/app.py", line 1951, in full_dispatch_request
    rv = self.handle_user_exception(e)
  File "/root/.venvs/testflask/lib/python3.6/site-packages/flask/app.py", line 1820, in handle_user_exception
    reraise(exc_type, exc_value, tb)
  File "/root/.venvs/testflask/lib/python3.6/site-packages/flask/_compat.py", line 39, in reraise
    raise value
  File "/root/.venvs/testflask/lib/python3.6/site-packages/flask/app.py", line 1949, in full_dispatch_request
    rv = self.dispatch_request()
  File "/root/.venvs/testflask/lib/python3.6/site-packages/flask/app.py", line 1935, in dispatch_request
    return self.view_functions[rule.endpoint](**req.view_args)
  File "/root/flaskapi/dev/OID/central6.py", line 76, in create
    parsed_entry=[(i,bytes(j,encoding='utf-8'))for i,j in entry.items()]
  File "/root/flaskapi/dev/OID/central6.py", line 76, in <listcomp>
    parsed_entry=[(i,bytes(j,encoding='utf-8'))for i,j in entry.items()]
TypeError: encoding without a string argument
 * Detected change in '/root/flaskapi/dev/OID/central6.py', reloading
 * Restarting with stat
 * Debugger is active!
 * Debugger PIN: 325-183-733
10.25.128.60 - - [03/Jun/2020 11:48:30] "POST /create HTTP/1.1" 500 -
Traceback (most recent call last):
  File "/root/.venvs/testflask/lib/python3.6/site-packages/flask/app.py", line 2463, in __call__
    return self.wsgi_app(environ, start_response)
  File "/root/.venvs/testflask/lib/python3.6/site-packages/flask/app.py", line 2449, in wsgi_app
    response = self.handle_exception(e)
  File "/root/.venvs/testflask/lib/python3.6/site-packages/flask/app.py", line 1866, in handle_exception
    reraise(exc_type, exc_value, tb)
  File "/root/.venvs/testflask/lib/python3.6/site-packages/flask/_compat.py", line 39, in reraise
    raise value
  File "/root/.venvs/testflask/lib/python3.6/site-packages/flask/app.py", line 2446, in wsgi_app
    response = self.full_dispatch_request()
  File "/root/.venvs/testflask/lib/python3.6/site-packages/flask/app.py", line 1951, in full_dispatch_request
    rv = self.handle_user_exception(e)
  File "/root/.venvs/testflask/lib/python3.6/site-packages/flask/app.py", line 1820, in handle_user_exception
    reraise(exc_type, exc_value, tb)
  File "/root/.venvs/testflask/lib/python3.6/site-packages/flask/_compat.py", line 39, in reraise
    raise value
  File "/root/.venvs/testflask/lib/python3.6/site-packages/flask/app.py", line 1949, in full_dispatch_request
    rv = self.dispatch_request()
  File "/root/.venvs/testflask/lib/python3.6/site-packages/flask/app.py", line 1935, in dispatch_request
    return self.view_functions[rule.endpoint](**req.view_args)
  File "/root/flaskapi/dev/OID/central6.py", line 77, in create
    parsed_entry["objectClass"]=[b"inetOrgPerson",b"orclUserV2"]
TypeError: list indices must be integers or slices, not str
 * Detected change in '/root/flaskapi/dev/OID/central6.py', reloading
 * Restarting with stat
  File "/root/flaskapi/dev/OID/central6.py", line 77
    parsed_entry.update("objectClass":[b"inetOrgPerson",b"orclUserV2"])
                                     ^
SyntaxError: invalid syntax
  File "central6.py", line 77
    parsed_entry.update("objectClass":[b"inetOrgPerson",b"orclUserV2"])
                                     ^
SyntaxError: invalid syntax
 * Serving Flask app "central6" (lazy loading)
 * Environment: production
   WARNING: This is a development server. Do not use it in a production deployment.
   Use a production WSGI server instead.
 * Debug mode: on
 * Running on http://10.21.74.44:5000/ (Press CTRL+C to quit)
 * Restarting with stat
 * Debugger is active!
 * Debugger PIN: 325-183-733
10.25.128.60 - - [03/Jun/2020 12:08:30] "POST /create HTTP/1.1" 500 -
Traceback (most recent call last):
  File "/root/.venvs/testflask/lib/python3.6/site-packages/flask/app.py", line 2463, in __call__
    return self.wsgi_app(environ, start_response)
  File "/root/.venvs/testflask/lib/python3.6/site-packages/flask/app.py", line 2449, in wsgi_app
    response = self.handle_exception(e)
  File "/root/.venvs/testflask/lib/python3.6/site-packages/flask/app.py", line 1866, in handle_exception
    reraise(exc_type, exc_value, tb)
  File "/root/.venvs/testflask/lib/python3.6/site-packages/flask/_compat.py", line 39, in reraise
    raise value
  File "/root/.venvs/testflask/lib/python3.6/site-packages/flask/app.py", line 2446, in wsgi_app
    response = self.full_dispatch_request()
  File "/root/.venvs/testflask/lib/python3.6/site-packages/flask/app.py", line 1951, in full_dispatch_request
    rv = self.handle_user_exception(e)
  File "/root/.venvs/testflask/lib/python3.6/site-packages/flask/app.py", line 1820, in handle_user_exception
    reraise(exc_type, exc_value, tb)
  File "/root/.venvs/testflask/lib/python3.6/site-packages/flask/_compat.py", line 39, in reraise
    raise value
  File "/root/.venvs/testflask/lib/python3.6/site-packages/flask/app.py", line 1949, in full_dispatch_request
    rv = self.dispatch_request()
  File "/root/.venvs/testflask/lib/python3.6/site-packages/flask/app.py", line 1935, in dispatch_request
    return self.view_functions[rule.endpoint](**req.view_args)
  File "/root/flaskapi/dev/OID/central6.py", line 77, in create
    parsed_entry.update({"objectClass":[b"inetOrgPerson",b"orclUserV2"]})
AttributeError: 'list' object has no attribute 'update'
 * Detected change in '/root/flaskapi/dev/OID/central6.py', reloading
 * Restarting with stat
 * Debugger is active!
 * Debugger PIN: 325-183-733
10.25.128.60 - - [03/Jun/2020 12:11:05] "POST /create HTTP/1.1" 500 -
 * Serving Flask app "central7" (lazy loading)
 * Environment: production
   WARNING: This is a development server. Do not use it in a production deployment.
   Use a production WSGI server instead.
 * Debug mode: on
 * Running on http://10.21.74.44:5000/ (Press CTRL+C to quit)
 * Restarting with stat
 * Debugger is active!
 * Debugger PIN: 325-183-733
10.25.129.202 - - [08/Jun/2020 16:19:15] "POST /create HTTP/1.1" 400 -
10.25.129.202 - - [08/Jun/2020 16:19:21] "POST /delete HTTP/1.1" 204 -
10.25.129.202 - - [08/Jun/2020 16:19:25] "POST /delete HTTP/1.1" 400 -
10.25.129.202 - - [08/Jun/2020 16:19:32] "POST /create HTTP/1.1" 201 -
10.25.129.202 - - [08/Jun/2020 16:21:35] "GET /search?username=test24.testSN24 HTTP/1.1" 200 -
10.25.129.202 - - [08/Jun/2020 16:28:48] "POST /activate HTTP/1.1" 500 -
Traceback (most recent call last):
  File "/root/.venvs/testflask/lib/python3.6/site-packages/flask/app.py", line 2463, in __call__
    return self.wsgi_app(environ, start_response)
  File "/root/.venvs/testflask/lib/python3.6/site-packages/flask/app.py", line 2449, in wsgi_app
    response = self.handle_exception(e)
  File "/root/.venvs/testflask/lib/python3.6/site-packages/flask/app.py", line 1866, in handle_exception
    reraise(exc_type, exc_value, tb)
  File "/root/.venvs/testflask/lib/python3.6/site-packages/flask/_compat.py", line 39, in reraise
    raise value
  File "/root/.venvs/testflask/lib/python3.6/site-packages/flask/app.py", line 2446, in wsgi_app
    response = self.full_dispatch_request()
  File "/root/.venvs/testflask/lib/python3.6/site-packages/flask/app.py", line 1951, in full_dispatch_request
    rv = self.handle_user_exception(e)
  File "/root/.venvs/testflask/lib/python3.6/site-packages/flask/app.py", line 1820, in handle_user_exception
    reraise(exc_type, exc_value, tb)
  File "/root/.venvs/testflask/lib/python3.6/site-packages/flask/_compat.py", line 39, in reraise
    raise value
  File "/root/.venvs/testflask/lib/python3.6/site-packages/flask/app.py", line 1949, in full_dispatch_request
    rv = self.dispatch_request()
  File "/root/.venvs/testflask/lib/python3.6/site-packages/flask/app.py", line 1935, in dispatch_request
    return self.view_functions[rule.endpoint](**req.view_args)
  File "/root/flaskapi/dev/OID/central7.py", line 435, in activate
    entry={"orclIsEnabled":data['status']}
KeyError: 'status'
 * Detected change in '/root/flaskapi/dev/OID/central7.py', reloading
{'desc': 'Already exists', 'info': 'Object already exists'}
 * Restarting with stat
 * Debugger is active!
 * Debugger PIN: 325-183-733
10.25.129.202 - - [08/Jun/2020 16:29:39] "POST /activate HTTP/1.1" 500 -
Traceback (most recent call last):
  File "/root/.venvs/testflask/lib/python3.6/site-packages/flask/app.py", line 2463, in __call__
    return self.wsgi_app(environ, start_response)
  File "/root/.venvs/testflask/lib/python3.6/site-packages/flask/app.py", line 2449, in wsgi_app
    response = self.handle_exception(e)
  File "/root/.venvs/testflask/lib/python3.6/site-packages/flask/app.py", line 1866, in handle_exception
    reraise(exc_type, exc_value, tb)
  File "/root/.venvs/testflask/lib/python3.6/site-packages/flask/_compat.py", line 39, in reraise
    raise value
  File "/root/.venvs/testflask/lib/python3.6/site-packages/flask/app.py", line 2446, in wsgi_app
    response = self.full_dispatch_request()
  File "/root/.venvs/testflask/lib/python3.6/site-packages/flask/app.py", line 1951, in full_dispatch_request
    rv = self.handle_user_exception(e)
  File "/root/.venvs/testflask/lib/python3.6/site-packages/flask/app.py", line 1820, in handle_user_exception
    reraise(exc_type, exc_value, tb)
  File "/root/.venvs/testflask/lib/python3.6/site-packages/flask/_compat.py", line 39, in reraise
    raise value
  File "/root/.venvs/testflask/lib/python3.6/site-packages/flask/app.py", line 1949, in full_dispatch_request
    rv = self.dispatch_request()
  File "/root/.venvs/testflask/lib/python3.6/site-packages/flask/app.py", line 1935, in dispatch_request
    return self.view_functions[rule.endpoint](**req.view_args)
  File "/root/flaskapi/dev/OID/central7.py", line 435, in activate
    entry={"orclIsEnabled":data['status']}
KeyError: 'status'
 * Detected change in '/root/flaskapi/dev/OID/central7.py', reloading
 * Restarting with stat
 * Debugger is active!
 * Debugger PIN: 325-183-733
10.25.129.202 - - [08/Jun/2020 16:30:01] "POST /activate HTTP/1.1" 200 -
10.25.129.202 - - [08/Jun/2020 16:34:53] "GET /listuser?role=Customer HTTP/1.1" 200 -
10.25.129.202 - - [08/Jun/2020 16:40:36] "GET /listuser?role=Customer HTTP/1.1" 200 -
10.25.129.202 - - [08/Jun/2020 16:42:24] "GET /listuser?role=Customer HTTP/1.1" 200 -
 * Detected change in '/root/flaskapi/dev/OID/central7.py', reloading
 * Restarting with stat
 * Debugger is active!
 * Debugger PIN: 325-183-733
10.25.129.202 - - [08/Jun/2020 17:00:09] "GET /search?username=test24.testSN24 HTTP/1.1" 200 -
10.25.129.202 - - [08/Jun/2020 17:00:30] "POST /updateuser HTTP/1.1" 200 -
10.25.129.202 - - [08/Jun/2020 17:00:35] "GET /search?username=test24.testSN24 HTTP/1.1" 200 -
 * Detected change in '/root/flaskapi/dev/OID/phoneverify.py', reloading
 * Restarting with stat
 * Debugger is active!
 * Debugger PIN: 325-183-733
10.25.135.117 - - [10/Jun/2020 12:49:09] "POST /create HTTP/1.1" 201 -
10.25.135.117 - - [10/Jun/2020 12:49:35] "POST /delete HTTP/1.1" 204 -
10.25.135.117 - - [10/Jun/2020 12:49:46] "POST /create HTTP/1.1" 400 -
10.25.135.117 - - [10/Jun/2020 12:50:07] "POST /create HTTP/1.1" 201 -
10.25.135.117 - - [10/Jun/2020 12:50:13] "POST /delete HTTP/1.1" 204 -
10.25.135.117 - - [10/Jun/2020 12:50:26] "POST /create HTTP/1.1" 400 -
10.25.135.117 - - [10/Jun/2020 12:50:40] "POST /create HTTP/1.1" 400 -
10.25.135.117 - - [10/Jun/2020 12:54:03] "GET /search?username=testuser@demo.com HTTP/1.1" 404 -
10.25.135.117 - - [10/Jun/2020 12:54:10] "POST /create HTTP/1.1" 400 -
10.25.135.117 - - [10/Jun/2020 12:54:14] "POST /create HTTP/1.1" 201 -
10.25.135.117 - - [10/Jun/2020 12:54:20] "GET /search?username=testuser@demo.com HTTP/1.1" 200 -
10.25.135.117 - - [10/Jun/2020 12:54:48] "POST /updateuser HTTP/1.1" 200 -
10.25.135.117 - - [10/Jun/2020 12:54:54] "GET /search?username=testuser@demo.com HTTP/1.1" 200 -
 * Detected change in '/root/flaskapi/dev/OID/phoneverify.py', reloading
 * Restarting with stat
Traceback (most recent call last):
  File "/root/flaskapi/dev/OID/central7.py", line 4, in <module>
    from phoneverify import pverify
  File "/root/flaskapi/dev/OID/phoneverify.py", line 8
    phoneToVerify = str(ph)
                          ^
IndentationError: unindent does not match any outer indentation level
Traceback (most recent call last):
  File "central7.py", line 4, in <module>
    from phoneverify import pverify
  File "/root/flaskapi/dev/OID/phoneverify.py", line 8
    phoneToVerify = str(ph)
                          ^
IndentationError: unindent does not match any outer indentation level
 * Serving Flask app "central7" (lazy loading)
 * Environment: production
   WARNING: This is a development server. Do not use it in a production deployment.
   Use a production WSGI server instead.
 * Debug mode: on
 * Running on http://10.21.74.44:5000/ (Press CTRL+C to quit)
 * Restarting with stat
 * Debugger is active!
 * Debugger PIN: 325-183-733
10.25.135.117 - - [10/Jun/2020 15:32:10] "POST /create HTTP/1.1" 400 -
 * Detected change in '/root/flaskapi/dev/OID/phoneverify.py', reloading
 * Restarting with stat
 * Debugger is active!
 * Debugger PIN: 325-183-733
10.25.135.117 - - [10/Jun/2020 15:35:05] "POST /create HTTP/1.1" 400 -
10.25.135.117 - - [10/Jun/2020 15:35:14] "POST /delete HTTP/1.1" 204 -
10.25.135.117 - - [10/Jun/2020 15:35:34] "POST /create HTTP/1.1" 201 -
10.25.135.117 - - [10/Jun/2020 15:35:45] "GET /search?username=testuser@demo.com HTTP/1.1" 200 -
10.25.135.117 - - [10/Jun/2020 15:36:00] "POST /create HTTP/1.1" 400 -
10.25.135.117 - - [10/Jun/2020 15:36:07] "POST /delete HTTP/1.1" 204 -
10.25.135.117 - - [10/Jun/2020 15:36:10] "POST /create HTTP/1.1" 201 -
10.25.135.117 - - [10/Jun/2020 15:36:22] "GET /search?username=testuser@demo.com HTTP/1.1" 200 -
 * Detected change in '/root/flaskapi/dev/OID/phoneverify.py', reloading
{'desc': 'Already exists', 'info': 'Object already exists'}
{'desc': 'Already exists', 'info': 'Object already exists'}
 * Restarting with stat
 * Debugger is active!
 * Debugger PIN: 325-183-733
10.25.135.117 - - [10/Jun/2020 15:39:23] "POST /create HTTP/1.1" 400 -
10.25.135.117 - - [10/Jun/2020 15:39:27] "POST /delete HTTP/1.1" 204 -
10.25.135.117 - - [10/Jun/2020 15:39:31] "GET /search?username=testuser@demo.com HTTP/1.1" 404 -
10.25.135.117 - - [10/Jun/2020 15:39:36] "POST /create HTTP/1.1" 201 -
10.25.135.117 - - [10/Jun/2020 15:39:56] "POST /delete HTTP/1.1" 204 -
10.25.135.117 - - [10/Jun/2020 15:40:05] "POST /create HTTP/1.1" 201 -
10.25.135.117 - - [10/Jun/2020 15:40:16] "GET /search?username=testuser@demo.com HTTP/1.1" 200 -
 * Detected change in '/root/flaskapi/dev/OID/phoneverify.py', reloading
{'desc': 'Already exists', 'info': 'Object already exists'}
 * Restarting with stat
 * Debugger is active!
 * Debugger PIN: 325-183-733
10.25.135.117 - - [10/Jun/2020 15:42:05] "POST /delete HTTP/1.1" 204 -
10.25.135.117 - - [10/Jun/2020 15:42:09] "POST /create HTTP/1.1" 201 -
 * Detected change in '/root/flaskapi/dev/OID/phoneverify.py', reloading
 * Restarting with stat
 * Debugger is active!
 * Debugger PIN: 325-183-733
10.25.135.117 - - [10/Jun/2020 15:42:45] "POST /delete HTTP/1.1" 204 -
10.25.135.117 - - [10/Jun/2020 15:42:48] "POST /create HTTP/1.1" 201 -
10.25.135.117 - - [10/Jun/2020 15:43:06] "POST /delete HTTP/1.1" 204 -
10.25.135.117 - - [10/Jun/2020 15:43:19] "POST /create HTTP/1.1" 400 -
10.25.135.117 - - [10/Jun/2020 15:43:27] "POST /create HTTP/1.1" 400 -
 * Detected change in '/root/flaskapi/dev/OID/phoneverify.py', reloading
 * Restarting with stat
 * Debugger is active!
 * Debugger PIN: 325-183-733
10.25.135.117 - - [10/Jun/2020 15:45:24] "POST /create HTTP/1.1" 201 -
 * Detected change in '/root/flaskapi/dev/OID/phoneverify.py', reloading
 * Restarting with stat
 * Debugger is active!
 * Debugger PIN: 325-183-733
10.25.135.117 - - [10/Jun/2020 15:46:10] "POST /delete HTTP/1.1" 204 -
10.25.135.117 - - [10/Jun/2020 15:46:19] "POST /create HTTP/1.1" 400 -
 * Detected change in '/root/flaskapi/dev/OID/phoneverify.py', reloading
 * Restarting with stat
 * Debugger is active!
 * Debugger PIN: 325-183-733
10.25.135.117 - - [10/Jun/2020 15:47:07] "POST /create HTTP/1.1" 400 -
10.25.135.117 - - [10/Jun/2020 15:47:14] "POST /create HTTP/1.1" 201 -
10.25.135.117 - - [10/Jun/2020 15:47:28] "POST /delete HTTP/1.1" 204 -
10.25.135.117 - - [10/Jun/2020 15:48:04] "POST /create HTTP/1.1" 201 -
10.25.135.117 - - [10/Jun/2020 15:48:10] "GET /search?username=testuser@demo.com HTTP/1.1" 200 -
10.25.128.40 - - [11/Jun/2020 18:43:13] code 400, message Bad request syntax ('\x03')
10.25.128.40 - - [11/Jun/2020 18:43:13] "" HTTPStatus.BAD_REQUEST -
 * Serving Flask app "central7" (lazy loading)
 * Environment: production
   WARNING: This is a development server. Do not use it in a production deployment.
   Use a production WSGI server instead.
 * Debug mode: on
 * Running on http://10.21.74.44:5000/ (Press CTRL+C to quit)
 * Restarting with stat
 * Debugger is active!
 * Debugger PIN: 325-183-733
 * Serving Flask app "central8" (lazy loading)
 * Environment: production
   WARNING: This is a development server. Do not use it in a production deployment.
   Use a production WSGI server instead.
 * Debug mode: on
 * Running on http://10.21.74.44:5000/ (Press CTRL+C to quit)
 * Restarting with stat
 * Debugger is active!
 * Debugger PIN: 325-183-733
